<mujoco model="mushr_car">
  <compiler meshdir="assets" />
  <asset>
    <mesh name="mushr_base_nano" file="mushr_base_nano.stl" />
    <mesh name="mushr_wheel" file="mushr_wheel.stl" />
    <mesh name="mushr_ydlidar" file="mushr_ydlidar.stl" />
  </asset>
  <default>
    <default class="mushr">
      <default class="wheel">
        <geom fitscale="1.2" type="ellipsoid" friction="2 0.005 0.0001" contype="1" conaffinity="0" mesh="mushr_wheel" mass="0.498952" />
      </default>
      <default class="steering">
        <joint type="hinge" axis="0 0 1" limited="true" frictionloss="0.01" damping="0.001" armature="0.0002" range="-0.38 0.38" />
      </default>
      <default class="throttle">
        <joint type="hinge" axis="0 1 0" frictionloss="0.001" damping="0.01" armature="0.01" limited="false" />
      </default>
    </default>
  </default>
  <worldbody>
    <body name="buddy" pos="0.0 0.0 0.0" euler="0 0 0.0">
      <camera name="third_person" mode="fixed" pos="-2 0 0.5" xyaxes="0 -2 0 0.1 0 1.41"/>
      <joint type="free" />
      <site name="imu" pos="-0.005 0 .165" />
      <camera name="realsense_d435i" mode="fixed" pos="-0.005 0 .165" xyaxes="0 -2 0 0.1 0 1.41" />

      <geom pos="0 0 0.094655" type="mesh" mass="3.542137" mesh="mushr_base_nano" />
      <geom name="realsense_d435i" size="0.012525 0.045 0.0125" pos="0.0123949 0 0.162178" mass="0.072" type="box" />
      <geom name="ydlidar" pos="-0.035325 0 0.202405" type="mesh" mass="0.180" mesh="mushr_ydlidar" />

      <body name="steering_wheel" pos="0.1385 0 0.0488">
        <joint class="steering" name="steering_wheel" />
        <geom class="wheel" contype="0" conaffinity="0" mass="0.01" rgba="0 0 0 0.01" />
      </body>
      <body name="wheel_fl" pos="0.1385 0.115 0.0488">
        <joint class="steering" name="wheel_fl_steering" />
        <joint class="throttle" name="wheel_fl_throttle" />
        <geom class="wheel" />
        <geom class="wheel" type="mesh" contype="0" conaffinity="0" group="1" rgba="1 1 1 0.3" />
      </body>
      <body name="wheel_fr" pos="0.1385 -0.115 0.0488">
        <joint class="steering" name="wheel_fr_steering" />
        <joint class="throttle" name="wheel_fr_throttle" />
        <geom class="wheel" />
        <geom class="wheel" type="mesh" contype="0" conaffinity="0" group="1" rgba="1 1 1 0.3" />
      </body>
      <body name="wheel_bl" pos="-0.158 0.115 0.0488">
        <joint class="throttle" name="wheel_bl_throttle" />
        <geom class="wheel" />
        <geom class="wheel" type="mesh" contype="0" conaffinity="0" group="1" rgba="1 1 1 0.3" />
      </body>
      <body name="wheel_br" pos="-0.158 -0.115 0.0488">
        <joint class="throttle" name="wheel_br_throttle" />
        <geom class="wheel" />
        <geom class="wheel" type="mesh" contype="0" conaffinity="0" group="1" rgba="1 1 1 0.3" />
      </body>
    </body>
  </worldbody>
  <actuator>
    <position class="steering" kp="25.0" name="steering" joint="steering_wheel" />
    <velocity kv="100" gear="0.04" forcelimited="true" forcerange="-500 500" name="throttle_velocity" tendon="throttle" />
  </actuator>
  <equality>
    <!-- taylor expansion of delta_l = arctan(L/(L/tan(delta) - W/2)) with L,W in reference to kinematic car model -->
    <joint joint1="wheel_fl_steering" joint2="steering_wheel" polycoef="0 1 0.375 0.140625 -0.0722656" />

    <!-- taylor expansion of delta_r = arctan(L/(L/tan(delta) + W/2)) with L,W in reference to kinematic car model -->
    <joint joint1="wheel_fr_steering" joint2="steering_wheel" polycoef="0 1 -0.375 0.140625 0.0722656" />
  </equality>
  <tendon>
    <fixed name="throttle">
      <joint joint="wheel_fl_throttle"  coef="0.25" />
      <joint joint="wheel_fr_throttle" coef="0.25" />
      <joint joint="wheel_bl_throttle" coef="0.25" />
      <joint joint="wheel_br_throttle" coef="0.25" />
    </fixed>
  </tendon>
  <sensor>
    <gyro name="gyro" site="imu" />
    <velocimeter name="velocimeter" site="imu" />
    <accelerometer name="accelerometer" site="imu" />
  </sensor>
</mujoco>