<mujoco model="objects">
	
	<default>
		<default class="dynamic_objects">
			<default class="dynamic_object">
				<geom type="cylinder" pos="0 0 0" size="0 0 0" euler="0 0 0" mass="5"/>
			</default>
		</default>
		<default class="dynamic_object_joint">
			<joint type="slide" axis="0 1 0" limited="true" range="0 100" frictionloss="0.01" damping="150" armature="0.002"/>
		</default>
	</default>
	
	<worldbody>
		<body name="dynamic_object_body_1" pos="-1 0 1">
			<site name="dynamic_object_1_link" pos="0 0 0" size="0.01 0.01 0.01"/>
			<joint class="dynamic_object_joint" name="dynamic_object_joint_1" axis="1 0 0" />				
			<geom name="dynamic_object_1" class="dynamic_object" pos="0 0 0" size="0.2 1"/>
		</body>
		<body name="dynamic_object_body_2" pos="10 1 1">
			<site name="dynamic_object_2_link" pos="0 0 0" size="0.001 0.001 0.001"/>
			<joint class="dynamic_object_joint" name="dynamic_object_joint_2" axis="1 0 0"/>				
			<geom name="dynamic_object_2" class="dynamic_object" pos="0 0 0" size="0.2 1"/>
		</body>
		<body name="dynamic_object_body_3" pos="-11 -1 1">
			<site name="dynamic_object_3_link" pos="0 0 0" size="0.001 0.001 0.001"/>
			<joint class="dynamic_object_joint" name="dynamic_object_joint_3" axis="-1 0 0"/>				
			<geom name="dynamic_object_3" class="dynamic_object" pos="0 0 0" size="0.2 1"/>
		</body>
	</worldbody>
	
	<actuator>
		<position  gear="20" class="dynamic_object_joint" kp="100" name="dynamic_object_1" joint="dynamic_object_joint_1" ctrlrange ="0 100" ctrllimited="true" />
		<position  gear="20" class="dynamic_object_joint" kp="100" name="dynamic_object_2" joint="dynamic_object_joint_2" ctrlrange ="0 100" ctrllimited="true" />
		<position  gear="20" class="dynamic_object_joint" kp="100" name="dynamic_object_3" joint="dynamic_object_joint_3" ctrlrange ="0 100" ctrllimited="true" />
	</actuator>
	
</mujoco>
